<!-- woohoo soham's project (mujoco sim boutta be dope fr)-->


<mujoco model="Soham Furuta Pendulum">
    <option timestep="0.0005" iterations="50" solver="Newton" tolerance="1e-10"/>
    <compiler angle="degree" coordinate="local" inertiafromgeom="true"/>

    
     <asset>
        <mesh name="base" file="base (1).stl" scale="0.001 0.001 0.001"/>
        <mesh name="legs" file="legs.stl" scale="0.001 0.001 0.001"/>
        <mesh name="n20" file="n20.stl" scale="0.001 0.001 0.001"/>
        <mesh name="n20bracket" file="n20bracket.stl" scale="0.001 0.001 0.001"/>
        <mesh name="horiarm" file="horiarm.stl" scale="0.001 0.001 0.001"/>
        <mesh name="as5600bracket" file="as5600bracket.stl" scale="0.001 0.001 0.001"/>
        <mesh name="as5600" file="as5600.stl" scale="0.001 0.001 0.001"/>
        <mesh name="pend" file="pend.stl" scale="0.001 0.001 0.001"/>
        <mesh name="bearingbracket" file="bearingbracket.stl" scale="0.001 0.001 0.001"/>
        <mesh name="bearing" file="bearing.stl" scale="0.001 0.001 0.001"/>
        <mesh name="washer" file="washer.stl" scale="0.001 0.001 0.001"/>
        <mesh name="magnetbracket" file="magnetbracket.stl" scale="0.001 0.001 0.001"/>
    </asset>

    <worldbody>

        <body name="base" pos="0 0 0">
            <geom type="mesh" mesh="base" rgba=".3 .3 .3 1"/>
            <geom type="mesh" mesh="legs" rgba=".3 .3 .3 1"/>
            <geom type="mesh" mesh="n20bracket" rgba=".3 .3 .3 1"/>
            <geom type="mesh" mesh="n20" rgba=".3 .3 .3 1"/>

            <body name="arm" pos="0 0 0">
               
                <joint name="arm" type="hinge" axis="0 0 1" damping="0.000" armature="0.000" frictionloss="0.00"/>
                <geom type="mesh" mesh="horiarm" rgba=".3 .3 .3 1"/>
                <geom type="mesh" mesh="as5600bracket" rgba=".3 .3 .3 1"/>
                <geom type="mesh" mesh="as5600" rgba=".3 .3 .3 1"/>
                <geom type="mesh" mesh="bearing" rgba=".3 .3 .3 1"/>
                <geom type="mesh" mesh="washer" rgba=".3 .3 .3 1"/>
                <geom type="mesh" mesh="bearingbracket" rgba=".3 .3 .3 1"/>
                <geom type="mesh" mesh="magnetbracket" rgba=".3 .3 .3 1"/>

                <body name="pole" pos="0 0.0476 0.1768"> <joint name="pend_joint" type="hinge" axis="0 1 0"/>
    
                    <geom type="mesh" mesh="pend" pos="0 -0.0476 -0.1768" rgba=".8 0 0 1"/>
                </body>
            </body>
        </body>
    </worldbody>


    <actuator>
        <velocity joint="arm" name="n20" kv=".1" ctrlrange="-52 52"/>
    </actuator>


</mujoco>